bioimageio_core_version: 0.5.3post2
bioimageio_spec_version: 0.4.5post7
error: '{''outputs'': {0: {''data_range'': [''Not a valid tuple.'']}, ''_schema'':
  [''Could not check for duplicate output tensor names due to another validation error.'']},
  ''weights'': defaultdict(<class ''dict''>, {''keras_hdf5'': {''value'': [''Errors
  in all options for this field. Fix any of the following errors:'', {''authors'':
  {0: [''Expected dictionary, but got str.'']}}, {''weights_format'': [''Must be equal
  to onnx.''], ''authors'': {0: [''Expected dictionary, but got str.'']}}, {''weights_format'':
  [''Must be equal to tensorflow_js.''], ''authors'': {0: [''Expected dictionary,
  but got str.'']}}, {''weights_format'': [''Must be equal to tensorflow_saved_model_bundle.''],
  ''authors'': {0: [''Expected dictionary, but got str.'']}}, {''weights_format'':
  [''Must be equal to torchscript.''], ''authors'': {0: [''Expected dictionary, but
  got str.'']}}, {''weights_format'': [''Must be equal to pytorch_state_dict.''],
  ''authors'': {0: [''Expected dictionary, but got str.'']}, ''architecture'': [''Missing
  data for required field.'']}]}, ''tensorflow_saved_model_bundle'': {''value'': [''Errors
  in all options for this field. Fix any of the following errors:'', {''authors'':
  {0: [''Expected dictionary, but got str.'']}}, {''weights_format'': [''Must be equal
  to keras_hdf5.''], ''authors'': {0: [''Expected dictionary, but got str.'']}}, {''weights_format'':
  [''Must be equal to onnx.''], ''authors'': {0: [''Expected dictionary, but got str.'']}},
  {''weights_format'': [''Must be equal to tensorflow_js.''], ''authors'': {0: [''Expected
  dictionary, but got str.'']}}, {''weights_format'': [''Must be equal to torchscript.''],
  ''authors'': {0: [''Expected dictionary, but got str.'']}}, {''weights_format'':
  [''Must be equal to pytorch_state_dict.''], ''authors'': {0: [''Expected dictionary,
  but got str.'']}, ''architecture'': [''Missing data for required field.'']}]}}),
  ''inputs'': {0: {''preprocessing'': {0: {''name'': [''Missing data for required
  field.''], ''scale_range'': [''Unknown field.'']}}, ''data_range'': [''Not a valid
  tuple.'']}, ''_schema'': [''Could not check for duplicate input tensor names due
  to another validation error.'']}, ''packaged_by'': {0: [''Expected dictionary, but
  got str.'']}, ''root_path'': [''Unknown field.'']}'
name: reproduce test outputs with deepimagej 2.1.13 using keras_hdf5 weights
reason: error
status: failed
traceback: ["  File \"/home/runner/work/models/models/scripts/check_rdf_and_test_model.py\",
    line 45, in test_model\n    model = load_resource_description(\n", "  File \"/usr/share/miniconda3/envs/deepImageJEnv/lib/python3.8/site-packages/bioimageio/core/resource_io/io_.py\",
    line 47, in load_resource_description\n    raw_rd = load_raw_resource_description(source,
    update_to_format=\"latest\")\n", "  File \"/usr/share/miniconda3/envs/deepImageJEnv/lib/python3.8/site-packages/bioimageio/spec/io_.py\",
    line 197, in load_raw_resource_description\n    raw_rd = schema.load(data)\n",
  "  File \"/usr/share/miniconda3/envs/deepImageJEnv/lib/python3.8/site-packages/marshmallow/schema.py\",
    line 717, in load\n    return self._do_load(\n", "  File \"/usr/share/miniconda3/envs/deepImageJEnv/lib/python3.8/site-packages/marshmallow/schema.py\",
    line 900, in _do_load\n    raise exc\n"]
